Workbook
Name UPDATE: #REF!
Name UPDATE: #REF!
Name UPDATE: #REF!
Name UPDATE: #REF!
Name UPDATE: #REF!
Name UPDATE: #REF!
Name UPDATE: #REF!

Sheet Cover Page
E5: DABUR INDIA LTD.
E7: FINANCIAL MODEL AND BUSINESS VALUATION
E9: Company : Dabur India Ltd
E10: Ticker : NSE: Dabur | J10: xxxx | K10: Inputs / Assumptions
E11: Industry : FMCG | J11: xxxx | K11: Formulae
E12: Year Ending : March | J12: xxxx | K12: Linking/ Reference cell
E13: Analyst : Saurav Sarthak Das
E16: EIC Analysis'
E17: Full 3 FS Model & DCF'!A1 - 3statments
E18: Full 3 FS Model & DCF'!A89 - Supporting Schedules
E19: Full 3 FS Model & DCF'!A111 - Ratio & Assumptions
E20: Full 3 FS Model & DCF'!A130 - DCF Analysis
E21: Full 3 FS Model & DCF'!A177 - Sensitivity Analysis
E22: Other Key Financial Ratio'!A6
E23: Common-Size Statement'!A9
E24: Comp- Valuation- Dabur'!A6
E25: WACC Calculation'!A6
E26: Football Field Analysis'!A6
... E31: Recommendation!A6

Sheet EIC Analysis
B1: Dabur India Ltd.
B4: EIC Analysis
B6: EIC Analysis - Dabur India Ltd.
B7: Parent Company | C7: Dabur India Limited (Burman Family)
B8: Category | C8: Consumer Products, Healthcare, Personal Care, Food & Beverages
B9: Sector | C9: FMCG
B10: Tagline/ Slogan | C10: Celebrate Life
B11: USP | C11: Dabur is India’s largest Ayurvedic and natural healthcare FMCG company with strong heritage, wide rural reach, and a diversified portfolio across health supplements, personal care, home care, and foods.
B13: Economic Analysis - Dabur India Ltd.
B14: Real GDP or Gross Domestic Product (GDP) at constant (2011–12) prices for 2024–25 is projected to reach ₹175–178 trillion, supported by resilient domestic consumption, robust manufacturing activity, and strong government capital expenditure. India remains one of the fastest-growing major economies, with the IMF forecasting 6.8% GDP growth for FY25, reflecting broad-based economic momentum and stable macroeconomic fundamentals.
B16: According to the latest estimates, India continues to strengthen its global economic position. The country has emerged as the world’s third-largest startup ecosystem, with rising investments in technology, digital services, and consumer-focused sectors. The expanding innovation ecosystem is expected to generate large-scale employment and boost consumer demand—an important growth driver for FMCG companies like Dabur.
B19: To sustain high economic growth through 2030, India needs to create significant employment opportunities. As per McKinsey Global Institute, India must generate 8–9 million non-farm jobs annually to maintain productivity and achieve 7–8% GDP growth through the remainder of the decade. Improving rural income levels, favorable monsoon trends, and rising government spending on agriculture and rural infrastructure are expected to boost rural consumption, directly benefitting Dabur, which has one of the deepest rural distribution networks in the FMCG sector.
B27: Industry Analysis - Dabur India Ltd.
B29: STP of Dabur
B30: Segment | C30: Ayurvedic, natural and herbal healthcare products, personal care, home care, and food & beverage products for daily use
B31: Target Group | C31: Health-conscious consumers, families across urban and rural India, and individuals seeking natural, herbal, and immunity-focused products
B32: Positioning | C32: India’s most trusted Ayurvedic and natural wellness FMCG brand offering science-based, nature-derived products that promote holistic health and everyday well-being
B34: SWOT ANALYSIS
B55: PESTEL ANALYSIS
B73: PORTER'S FIVE FORCES ANALYSIS
B75: Competition Rivalry (High)
B76: Dabur faces intense competition from major FMCG players such as HUL, Patanjali, Emami, Marico, Baidyanath, and ITC. Most competitors offer similar Ayurvedic, natural, and healthcare products, making product switching easy for consumers.In segments like honey, oral care, juices, and healthcare supplements, multiple brands compete aggressively, increasing advertising and pricing pressures.
B80: Threat of new entrants (Moderate)
B81: While the FMCG sector is easy to enter at a small scale, building a trusted Ayurvedic brand like Dabur is challenging due to: High cost of brand building,Extensive distribution networks required,Regulatory approvals for health productsHowever, growing demand for natural and Ayurvedic products continues to attract start-ups and D2C wellness brands, keeping the threat at a moderate level.
B85: Threat of substitutes (Moderate-High)
B86: Consumers are increasingly shifting towards: Local Ayurvedic brands Herbal home remedies Organic and specialty wellness products In segments like honey, chyawanprash, and juices, substitutes are widely available. The wellness industry is expanding rapidly, increasing alternatives, but Dabur’s strong trust and legacy reduce the risk slightly.
B90: Bargaining power of suppliers (Low-Moderate)
B91: Dabur sources raw materials like herbs, fruits, and natural ingredients largely from domestic suppliers. Because most ingredients have many alternate suppliers, the bargaining power remains low. However, for specific herbs and organic-certified materials, supplier dependency can increase, making overall power low to moderate.
B94: Bargaining power of consumers (High)
... B101: Dabur India Ltd is one of the largest Ayurvedic and natural FMCG companies in India, with a legacy of over 140 years. The company operates across healthcare, personal care, home care, and food & beverages, with trusted brands such as Dabur Honey, Dabur Amla, Vatika, Real Juices, Dabur Red Toothpaste, Chyawanprash, and Pudin Hara. Dabur reaches over 6.9 million retail outlets and has a strong footprint in both urban and rural markets, including deep distribution in Tier-2 and Tier-3 regions. It also has a strong international presence across the Middle East, Africa, SAARC, and the US. With a market capitalization of USD 10–11 billion, Dabur is among the top Indian FMCG players and a global leader in Ayurvedic healthcare products. Its portfolio strongly aligns with growing wellness trends and the shift toward natural, herbal, and immunity-boosting products.
B115: Revenue from each segment | C115: Percent(%)
B116: Consumer Care Business | C116: 0.55
B117: Food & Beverages Business | C117: 0.155
B118: Other Segments | C118: 0.03
B119: International Business | C119: 0.265
B122: Back to cover

Sheet Full 3 FS Model & DCF
A1: Dabur India Ltd. | J1: Historical Period | P1: Forecasted Period
A4: Financial Statements | J4: 2020 | K4: =J4+1 -> 2021 | L4: =K4+1 -> 2022 | M4: =L4+1 -> 2023 | N4: =M4+1 -> 2024 | O4: =N4+1 -> 2025 | P4: =O4+1 -> 2026 | Q4: =P4+1 -> 2027 | R4: =Q4+1 -> 2028 | ... T4: =S4+1 -> 2030
A6: Income Statement
C7: (All figures in INR crores)
B9: Income
C10: Revenue | J10: ='Historical Statement'!H9 -> 8703.59 | K10: ='Historical Statement'!I9 -> 9561.65 | L10: ='Historical Statement'!J9 -> 10888.68 | M10: ='Historical Statement'!K9 -> 11529.89 | N10: ='Historical Statement'!L9 -> 12404.01 | O10: ='Historical Statement'!M9 -> 12563.09 | P10: =O10*(1+P115) -> 13530.196 | Q10: =P10*(1+Q115) -> 14519.672 | R10: =Q10*(1+R115) -> 15528.417 | S10: =R10*(1+S115) -> 16553.303 | T10: =S10*(1+T115) -> 17591.205
C11: Cost of Good Sold | J11: =-SUM('Historical Statement'!H13:H16) -> -4360.24 | K11: =-SUM('Historical Statement'!I13:I16) -> -4788.96 | L11: =-SUM('Historical Statement'!J13:J16) -> -5639.69 | M11: =-SUM('Historical Statement'!K13:K16) -> -6268.67 | N11: =-SUM('Historical Statement'!L13:L16) -> -6446.96 | O11: =-SUM('Historical Statement'!M13:M16) -> -6534.86 | P11: =-P10*O118 -> -7037.9131 | Q11: =-Q10*P118 -> -7509.9658 | R11: =-R10*Q118 -> -8031.7161 | S11: =-S10*R118 -> -8561.8147 | T11: =-T10*S118 -> -9098.6459
C12: Gross Profit | J12: =SUM(J10:J11) -> 4343.35 | K12: =SUM(K10:K11) -> 4772.69 | L12: =SUM(L10:L11) -> 5248.99 | M12: =SUM(M10:M11) -> 5261.22 | N12: =SUM(N10:N11) -> 5957.05 | O12: =SUM(O10:O11) -> 6028.23 | P12: =SUM(P10:P11) -> 6492.2827 | Q12: =SUM(Q10:Q11) -> 7009.7058 | ... T12: =SUM(T10:T11) -> 8492.5595
B13: Expenses
C14: Salaries and Benefit expenses | J14: =-'Historical Statement'!H17 -> -947.74 | K14: =-'Historical Statement'!I17 -> -1033.46 | L14: =-'Historical Statement'!J17 -> -1079.95 | M14: =-'Historical Statement'!K17 -> -1137 | N14: =-'Historical Statement'!L17 -> -1239.56 | O14: =-'Historical Statement'!M17 -> -1291.23 | P14: =-P10*P120 -> -1392.439 | Q14: =-Q10*Q120 -> -1494.2694 | R14: =-R10*R120 -> -1598.0828 | S14: =-S10*S120 -> -1703.5574 | T14: =-T10*T120 -> -1810.3715
C15: Other Expenses | J15: =-'Historical Statement'!H20 -> -1603.26 | K15: =-'Historical Statement'!I20 -> -1736.55 | L15: =-'Historical Statement'!J20 -> -1915.23 | M15: =-'Historical Statement'!K20 -> -1960.1 | N15: =-'Historical Statement'!L20 -> -2317.26 | O15: =-'Historical Statement'!M20 -> -2420.66 | P15: =-P10*P123 -> -2460.7188 | Q15: =-Q10*Q123 -> -2640.6735 | R15: =-R10*R123 -> -2824.1326 | S15: =-S10*S123 -> -3010.5273 | T15: =-T10*T123 -> -3199.2892
C16: EBITDA | J16: =SUM(J12:J15) -> 1792.35 | K16: =SUM(K12:K15) -> 2002.68 | L16: =SUM(L12:L15) -> 2253.81 | M16: =SUM(M12:M15) -> 2164.12 | N16: =SUM(N12:N15) -> 2400.23 | O16: =SUM(O12:O15) -> 2316.34 | P16: =SUM(P12:P15) -> 2639.1249 | Q16: =SUM(Q12:Q15) -> 2874.763 | ... T16: =SUM(T12:T15) -> 3482.8988
C17: Depreciation and amortisation expense | J17: =-'Historical Statement'!H19 -> -220.45 | K17: =-'Historical Statement'!I19 -> -240.13 | L17: =-'Historical Statement'!J19 -> -252.89 | M17: =-'Historical Statement'!K19 -> -310.96 | N17: =-'Historical Statement'!L19 -> -399.21 | O17: =-'Historical Statement'!M19 -> -445.6 | P17: =P101 -> -466.09181 | Q17: =Q101 -> -439.43245 | R17: =R101 -> -413.13186 | S17: =S101 -> -387.675 | T17: =T101 -> -363.33744
C18: EBIT | J18: =SUM(J16:J17) -> 1571.9 | K18: =SUM(K16:K17) -> 1762.55 | L18: =SUM(L16:L17) -> 2000.92 | M18: =SUM(M16:M17) -> 1853.16 | N18: =SUM(N16:N17) -> 2001.02 | O18: =SUM(O16:O17) -> 1870.74 | P18: =SUM(P16:P17) -> 2173.0331 | Q18: =SUM(Q16:Q17) -> 2435.3306 | ... T18: =SUM(T16:T17) -> 3119.5614
C19: Interest | J19: =-'Historical Statement'!H18 -> -49.54 | K19: =-'Historical Statement'!I18 -> -30.81 | L19: =-'Historical Statement'!J18 -> -38.6 | M19: =-'Historical Statement'!K18 -> -78.24 | N19: =-'Historical Statement'!L18 -> -124.18 | O19: =-'Historical Statement'!M18 -> -163.5 | P19: =P108 -> -109.03195 | Q19: =Q108 -> -109.03195 | R19: =R108 -> -109.03195 | S19: =S108 -> -109.03195 | T19: =T108 -> -109.03195
C20: Other Income (Expenses) | J20: =SUM('Historical Statement'!H10+'Historical Statement'!H26) -> 205.29 | K20: =SUM('Historical Statement'!I10+'Historical Statement'!I26) -> 325.29 | L20: =SUM('Historical Statement'!J10+'Historical Statement'!J26) -> 308.16 | M20: =SUM('Historical Statement'!K10+'Historical Statement'!K26) -> 445.39 | N20: =SUM('Historical Statement'!L10+'Historical Statement'!L26) -> 482.41 | O20: =SUM('Historical Statement'!M10+'Historical Statement'!M26) -> 550.1 | P20: =P10*P132 -> 467.27809 | Q20: =Q10*Q132 -> 501.45057 | R20: =R10*R132 -> 536.28854 | S20: =S10*S132 -> 571.68394 | T20: =T10*T132 -> 607.52889
C21: Earning Before Tax | J21: =SUM(J18:J20) -> 1727.65 | K21: =SUM(K18:K20) -> 2057.03 | L21: =SUM(L18:L20) -> 2270.48 | M21: =SUM(M18:M20) -> 2220.31 | N21: =SUM(N18:N20) -> 2359.25 | O21: =SUM(O18:O20) -> 2257.34 | P21: =SUM(P18:P20) -> 2531.2793 | Q21: =SUM(Q18:Q20) -> 2827.7492 | ... T21: =SUM(T18:T20) -> 3618.0583
C22: Tax | J22: =-'Historical Statement'!H31 -> -279.72 | K22: =-'Historical Statement'!I31 -> -361.07 | L22: =-'Historical Statement'!J31 -> -526.38 | M22: =-'Historical Statement'!K31 -> -517.35 | N22: =-'Historical Statement'!L31 -> -547.43 | O22: =-'Historical Statement'!M31 -> -517.47 | P22: =-P21*P135 -> -533.06904 | Q22: =-Q21*Q135 -> -595.50345 | R22: =-R21*R135 -> -650.43888 | S22: =-S21*S135 -> -705.987 | T22: =-T21*T135 -> -761.93682
C23: Net Profit | J23: =SUM(J21:J22) -> 1447.93 | K23: =SUM(K21:K22) -> 1695.96 | L23: =SUM(L21:L22) -> 1744.1 | M23: =SUM(M21:M22) -> 1702.96 | N23: =SUM(N21:N22) -> 1811.82 | O23: =SUM(O21:O22) -> 1739.87 | P23: =SUM(P21:P22) -> 1998.2102 | Q23: =SUM(Q21:Q22) -> 2232.2457 | ... T23: =SUM(T21:T22) -> 2856.1215
A25: Balance Sheet
B27: Assets
C28: Current Assets:
D29: Cash | J29: ='Historical Statement'!H64 -> 163.94 | K29: ='Historical Statement'!I64 -> 241.23 | L29: ='Historical Statement'!J64 -> 255.91 | M29: ='Historical Statement'!K64 -> 146.82 | N29: ='Historical Statement'!L64 -> 247.6 | O29: ='Historical Statement'!M64 -> 111.97 | P29: =P87 -> 1063.201 | Q29: =Q87 -> 2380.0817 | R29: =R87 -> 3797.5188 | S29: =S87 -> 5312.9126 | T29: =T87 -> 6926.0365
D30: Bank deposits | J30: ='Historical Statement'!H65 -> 647.43 | K30: ='Historical Statement'!I65 -> 1087.8 | L30: ='Historical Statement'!J65 -> 314.23 | M30: ='Historical Statement'!K65 -> 179.1 | N30: ='Historical Statement'!L65 -> 418.76 | O30: ='Historical Statement'!M65 -> 393.74 | P30: =O30 -> 393.74 | Q30: =P30 -> 393.74 | R30: =Q30 -> 393.74 | S30: =R30 -> 393.74 | T30: =S30 -> 393.74
D31: Accounts Receivables | J31: ='Historical Statement'!H63 -> 813.89 | K31: ='Historical Statement'!I63 -> 561.58 | L31: ='Historical Statement'!J63 -> 646.15 | M31: ='Historical Statement'!K63 -> 848.75 | N31: ='Historical Statement'!L63 -> 898.72 | O31: ='Historical Statement'!M63 -> 888.5 | P31: =(P10*P141)/365 -> 966.00192 | Q31: =(Q10*Q141)/365 -> 1036.6465 | R31: =(R10*R141)/365 -> 1108.6669 | S31: =(S10*S141)/365 -> 1181.8397 | T31: =(T10*T141)/365 -> 1255.9418
D32: Inventory | J32: ='Historical Statement'!H60 -> 1379.57 | K32: ='Historical Statement'!I60 -> 1734.28 | L32: ='Historical Statement'!J60 -> 1911.37 | M32: ='Historical Statement'!K60 -> 2024.2 | N32: ='Historical Statement'!L60 -> 1946.97 | O32: ='Historical Statement'!M60 -> 2300.11 | P32: =-(P11*P147)/365 -> 2339.3248 | Q32: =-(Q11*Q147)/365 -> 2496.23 | R32: =-(R11*R147)/365 -> 2669.654 | S32: =-(S11*S147)/365 -> 2845.853 | T32: =-(T11*T147)/365 -> 3024.2898
D33: Other Current Assets | J33: ='Historical Statement'!H69+'Historical Statement'!H68 -> 468.44 | K33: ='Historical Statement'!I69+'Historical Statement'!I68 -> 387.36 | L33: ='Historical Statement'!J69+'Historical Statement'!J68 -> 298.11 | M33: ='Historical Statement'!K69+'Historical Statement'!K68 -> 284.65 | N33: ='Historical Statement'!L69+'Historical Statement'!L68 -> 458.46 | O33: ='Historical Statement'!M69+'Historical Statement'!M68 -> 634.27 | P33: =O33 -> 634.27 | Q33: =P33 -> 634.27 | R33: =Q33 -> 634.27 | S33: =R33 -> 634.27 | T33: =S33 -> 634.27
C35: Non-current Assets:
D36: Property, plant and equipment | J36: ='Historical Statement'!H43+'Historical Statement'!H44+'Historical Statement'!H45+'Historical Statement'!H47+'Historical Statement'!H48 -> 2063.28 | K36: ='Historical Statement'!I43+'Historical Statement'!I44+'Historical Statement'!I45+'Historical Statement'!I47+'Historical Statement'!I48 -> 2054.21 | L36: ='Historical Statement'!J43+'Historical Statement'!J44+'Historical Statement'!J45+'Historical Statement'!J47+'Historical Statement'!J48 -> 2224.25 | M36: ='Historical Statement'!K43+'Historical Statement'!K44+'Historical Statement'!K45+'Historical Statement'!K47+'Historical Statement'!K48 -> 3348.53 | N36: ='Historical Statement'!L43+'Historical Statement'!L44+'Historical Statement'!L45+'Historical Statement'!L47+'Historical Statement'!L48 -> 3642.11 | O36: ='Historical Statement'!M43+'Historical Statement'!M44+'Historical Statement'!M45+'Historical Statement'!M47+'Historical Statement'!M48 -> 3753.59 | P36: =P102 -> 3538.8935 | Q36: =Q102 -> 3327.0861 | R36: =R102 -> 3122.0738 | S36: =S102 -> 2926.0754 | T36: =T102 -> 2740.2496
D37: Goodwill | J37: ='Historical Statement'!H46 -> 335.97 | K37: ='Historical Statement'!I46 -> 336.01 | L37: ='Historical Statement'!J46 -> 251.15 | M37: ='Historical Statement'!K46 -> 405.25 | N37: ='Historical Statement'!L46 -> 405.12 | O37: ='Historical Statement'!M46 -> 405.09 | P37: =O37 -> 405.09 | Q37: =P37 -> 405.09 | R37: =Q37 -> 405.09 | S37: =R37 -> 405.09 | T37: =S37 -> 405.09
D38: Financial Assets | J38: ='Historical Statement'!H51+'Historical Statement'!H52+'Historical Statement'!H53+'Historical Statement'!H62+'Historical Statement'!H66+'Historical Statement'!H67+'Historical Statement'!H71+'Historical Statement'!H49 -> 3369.34 | K38: ='Historical Statement'!I51+'Historical Statement'!I52+'Historical Statement'!I53+'Historical Statement'!I62+'Historical Statement'!I66+'Historical Statement'!I67+'Historical Statement'!I71+'Historical Statement'!I49 -> 4288.44 | L38: ='Historical Statement'!J51+'Historical Statement'!J52+'Historical Statement'!J53+'Historical Statement'!J62+'Historical Statement'!J66+'Historical Statement'!J67+'Historical Statement'!J71+'Historical Statement'!J49 -> 6279.45 | M38: ='Historical Statement'!K51+'Historical Statement'!K52+'Historical Statement'!K53+'Historical Statement'!K62+'Historical Statement'!K66+'Historical Statement'!K67+'Historical Statement'!K71+'Historical Statement'!K49 -> 6324.62 | N38: ='Historical Statement'!L51+'Historical Statement'!L52+'Historical Statement'!L53+'Historical Statement'!L62+'Historical Statement'!L66+'Historical Statement'!L67+'Historical Statement'!L71+'Historical Statement'!L49 -> 6996.03 | O38: ='Historical Statement'!M51+'Historical Statement'!M52+'Historical Statement'!M53+'Historical Statement'!M62+'Historical Statement'!M66+'Historical Statement'!M67+'Historical Statement'!M71+'Historical Statement'!M49 -> 7533.27 | P38: =O38 -> 7533.27 | Q38: =P38 -> 7533.27 | R38: =Q38 -> 7533.27 | S38: =R38 -> 7533.27 | T38: =S38 -> 7533.27
D39: Other Non-current Assets | J39: =SUM('Historical Statement'!H54:H56) -> 112.15 | K39: =SUM('Historical Statement'!I54:I56) -> 156.22 | L39: =SUM('Historical Statement'!J54:J56) -> 103.91 | M39: =SUM('Historical Statement'!K54:K56) -> 92.45 | N39: =SUM('Historical Statement'!L54:L56) -> 108.91 | O39: =SUM('Historical Statement'!M54:M56) -> 139.44 | P39: =O39 -> 139.44 | Q39: =P39 -> 139.44 | R39: =Q39 -> 139.44 | S39: =R39 -> 139.44 | T39: =S39 -> 139.44
D40: Total Assets | J40: =SUM(J29:J39) -> 9354.01 | K40: =SUM(K29:K39) -> 10847.13 | L40: =SUM(L29:L39) -> 12284.53 | M40: =SUM(M29:M39) -> 13654.37 | N40: =SUM(N29:N39) -> 15122.68 | O40: =SUM(O29:O39) -> 16159.98 | P40: =SUM(P29:P39) -> 17013.231 | Q40: =SUM(Q29:Q39) -> 18345.854 | ... T40: =SUM(T29:T39) -> 23052.328
B42: Liability
C43: Current Liabilities
D44: Accounts Payable | J44: =SUM('Historical Statement'!H98:H99) -> 1482.15 | K44: =SUM('Historical Statement'!I98:I99) -> 1915.26 | L44: =SUM('Historical Statement'!J98:J99) -> 2017.95 | M44: =SUM('Historical Statement'!K98:K99) -> 2186.61 | N44: =SUM('Historical Statement'!L98:L99) -> 2421.71 | O44: =SUM('Historical Statement'!M98:M99) -> 2825.34 | P44: =-(P11*P144)/365 -> 2644.4595 | Q44: =-(Q11*Q144)/365 -> 2821.8309 | R44: =-(R11*R144)/365 -> 3017.8759 | S44: =-(S11*S144)/365 -> 3217.0577 | T44: =-(T11*T144)/365 -> 3418.7693
D45: Other Current Liabilities | J45: =SUM('Historical Statement'!H100:H103) -> 677.49 | K45: =SUM('Historical Statement'!I100:I103) -> 644 | L45: =SUM('Historical Statement'!J100:J103) -> 664.43 | M45: =SUM('Historical Statement'!K100:K103) -> 692.23 | N45: =SUM('Historical Statement'!L100:L103) -> 849.87 | O45: =SUM('Historical Statement'!M100:M103) -> 1028.68 | P45: =O45 -> 1028.68 | Q45: =P45 -> 1028.68 | R45: =Q45 -> 1028.68 | S45: =R45 -> 1028.68 | T45: =S45 -> 1028.68
C46: Non-Current Liabilities
D47: Debt | J47: ='Historical Statement'!H86+'Historical Statement'!H87+'Historical Statement'!H95+'Historical Statement'!H96 -> 467.13 | K47: ='Historical Statement'!I86+'Historical Statement'!I87+'Historical Statement'!I95+'Historical Statement'!I96 -> 509.06 | L47: ='Historical Statement'!J86+'Historical Statement'!J87+'Historical Statement'!J95+'Historical Statement'!J96 -> 1030.1 | M47: ='Historical Statement'!K86+'Historical Statement'!K87+'Historical Statement'!K95+'Historical Statement'!K96 -> 1173.79 | N47: ='Historical Statement'!L86+'Historical Statement'!L87+'Historical Statement'!L95+'Historical Statement'!L96 -> 1365.09 | O47: ='Historical Statement'!M86+'Historical Statement'!M87+'Historical Statement'!M95+'Historical Statement'!M96 -> 878.07 | P47: =P107 -> 878.07 | Q47: =Q107 -> 878.07 | R47: =R107 -> 878.07 | S47: =S107 -> 878.07 | T47: =T107 -> 878.07
D48: Other Non-Current Liabilities | J48: ='Historical Statement'!H88+'Historical Statement'!H89+'Historical Statement'!H90 -> 85.03 | K48: ='Historical Statement'!I88+'Historical Statement'!I89+'Historical Statement'!I90 -> 78.59 | L48: ='Historical Statement'!J88+'Historical Statement'!J89+'Historical Statement'!J90 -> 150.2 | M48: ='Historical Statement'!K88+'Historical Statement'!K89+'Historical Statement'!K90 -> 160.31 | N48: ='Historical Statement'!L88+'Historical Statement'!L89+'Historical Statement'!L90 -> 182.93 | O48: ='Historical Statement'!M88+'Historical Statement'!M89+'Historical Statement'!M90 -> 217.63 | P48: =O48 -> 217.63 | Q48: =P48 -> 217.63 | R48: =Q48 -> 217.63 | S48: =R48 -> 217.63 | T48: =S48 -> 217.63
...

Sheet Other Key Financial Ratio
B1: Dabur India Ltd. | I1: Historical Period
B4: Key Financial Ratios | I4: 2020 | J4: =I4+1 -> 2021 | K4: =J4+1 -> 2022 | L4: =K4+1 -> 2023 | M4: =L4+1 -> 2024 | N4: =M4+1 -> 2025 | O4: Trends
B6: Profitability Ratio
B7: Operating Profit Margin | I7: ='Full 3 FS Model & DCF'!J16/'Full 3 FS Model & DCF'!J10 -> 0.20593226 | J7: ='Full 3 FS Model & DCF'!K16/'Full 3 FS Model & DCF'!K10 -> 0.20944921 | K7: ='Full 3 FS Model & DCF'!L16/'Full 3 FS Model & DCF'!L10 -> 0.20698652 | L7: ='Full 3 FS Model & DCF'!M16/'Full 3 FS Model & DCF'!M10 -> 0.1876965 | M7: ='Full 3 FS Model & DCF'!N16/'Full 3 FS Model & DCF'!N10 -> 0.19350436 | N7: ='Full 3 FS Model & DCF'!O16/'Full 3 FS Model & DCF'!O10 -> 0.18437661
B8: Net Profit Margin | I8: ='Full 3 FS Model & DCF'!J23/'Full 3 FS Model & DCF'!J10 -> 0.16636009 | J8: ='Full 3 FS Model & DCF'!K23/'Full 3 FS Model & DCF'!K10 -> 0.17737106 | K8: ='Full 3 FS Model & DCF'!L23/'Full 3 FS Model & DCF'!L10 -> 0.16017552 | L8: ='Full 3 FS Model & DCF'!M23/'Full 3 FS Model & DCF'!M10 -> 0.14769959 | M8: ='Full 3 FS Model & DCF'!N23/'Full 3 FS Model & DCF'!N10 -> 0.14606728 | N8: ='Full 3 FS Model & DCF'!O23/'Full 3 FS Model & DCF'!O10 -> 0.13849061
B10: Return Ratios
B11: ROA | I11: ='Full 3 FS Model & DCF'!J23/'Full 3 FS Model & DCF'!J40 -> 0.15479244 | J11: ='Full 3 FS Model & DCF'!K23/'Full 3 FS Model & DCF'!K40 -> 0.15635103 | K11: ='Full 3 FS Model & DCF'!L23/'Full 3 FS Model & DCF'!L40 -> 0.14197531 | L11: ='Full 3 FS Model & DCF'!M23/'Full 3 FS Model & DCF'!M40 -> 0.12471905 | M11: ='Full 3 FS Model & DCF'!N23/'Full 3 FS Model & DCF'!N40 -> 0.11980813 | N11: ='Full 3 FS Model & DCF'!O23/'Full 3 FS Model & DCF'!O40 -> 0.10766536
B12: ROE | I12: ='Full 3 FS Model & DCF'!J23/'Full 3 FS Model & DCF'!J54 -> 0.21919237 | J12: ='Full 3 FS Model & DCF'!K23/'Full 3 FS Model & DCF'!K54 -> 0.22130272 | K12: ='Full 3 FS Model & DCF'!L23/'Full 3 FS Model & DCF'!L54 -> 0.20809421 | L12: ='Full 3 FS Model & DCF'!M23/'Full 3 FS Model & DCF'!M54 -> 0.18978164 | M12: ='Full 3 FS Model & DCF'!N23/'Full 3 FS Model & DCF'!N54 -> 0.18363723 | N12: ='Full 3 FS Model & DCF'!O23/'Full 3 FS Model & DCF'!O54 -> 0.16108878
B13: ROCE | I13: ='Full 3 FS Model & DCF'!J18/('Full 3 FS Model & DCF'!J54+SUM('Full 3 FS Model & DCF'!J47:J48)) -> 0.21960321 | J13: ='Full 3 FS Model & DCF'!K18/('Full 3 FS Model & DCF'!K54+SUM('Full 3 FS Model & DCF'!K47:K48)) -> 0.21361187 | K13: ='Full 3 FS Model & DCF'!L18/('Full 3 FS Model & DCF'!L54+SUM('Full 3 FS Model & DCF'!L47:L48)) -> 0.20926623 | L13: ='Full 3 FS Model & DCF'!M18/('Full 3 FS Model & DCF'!M54+SUM('Full 3 FS Model & DCF'!M47:M48)) -> 0.17978998 | M13: ='Full 3 FS Model & DCF'!N18/('Full 3 FS Model & DCF'!N54+SUM('Full 3 FS Model & DCF'!N47:N48)) -> 0.17530786 | N13: ='Full 3 FS Model & DCF'!O18/('Full 3 FS Model & DCF'!O54+SUM('Full 3 FS Model & DCF'!O47:O48)) -> 0.15725275
B15: Liquidity Ratios
B16: Current ratio | I16: =('Full 3 FS Model & DCF'!J29+'Full 3 FS Model & DCF'!J30+'Full 3 FS Model & DCF'!J31+'Full 3 FS Model & DCF'!J32+'Full 3 FS Model & DCF'!J33)/('Full 3 FS Model & DCF'!J44+'Full 3 FS Model & DCF'!J45) -> 1.6082634 | J16: =('Full 3 FS Model & DCF'!K29+'Full 3 FS Model & DCF'!K30+'Full 3 FS Model & DCF'!K31+'Full 3 FS Model & DCF'!K32+'Full 3 FS Model & DCF'!K33)/('Full 3 FS Model & DCF'!K44+'Full 3 FS Model & DCF'!K45) -> 1.5677383 | K16: =('Full 3 FS Model & DCF'!L29+'Full 3 FS Model & DCF'!L30+'Full 3 FS Model & DCF'!L31+'Full 3 FS Model & DCF'!L32+'Full 3 FS Model & DCF'!L33)/('Full 3 FS Model & DCF'!L44+'Full 3 FS Model & DCF'!L45) -> 1.2771382 | L16: =('Full 3 FS Model & DCF'!M29+'Full 3 FS Model & DCF'!M30+'Full 3 FS Model & DCF'!M31+'Full 3 FS Model & DCF'!M32+'Full 3 FS Model & DCF'!M33)/('Full 3 FS Model & DCF'!M44+'Full 3 FS Model & DCF'!M45) -> 1.2100429 | M16: =('Full 3 FS Model & DCF'!N29+'Full 3 FS Model & DCF'!N30+'Full 3 FS Model & DCF'!N31+'Full 3 FS Model & DCF'!N32+'Full 3 FS Model & DCF'!N33)/('Full 3 FS Model & DCF'!N44+'Full 3 FS Model & DCF'!N45) -> 1.2136368 | N16: =('Full 3 FS Model & DCF'!O29+'Full 3 FS Model & DCF'!O30+'Full 3 FS Model & DCF'!O31+'Full 3 FS Model & DCF'!O32+'Full 3 FS Model & DCF'!O33)/('Full 3 FS Model & DCF'!O44+'Full 3 FS Model & DCF'!O45) -> 1.1231364
B17: Quick Ratio | I17: =('Full 3 FS Model & DCF'!J29+'Full 3 FS Model & DCF'!J30+'Full 3 FS Model & DCF'!J31+'Full 3 FS Model & DCF'!J33)/('Full 3 FS Model & DCF'!J44+'Full 3 FS Model & DCF'!J45) -> 0.96946713 | J17: =('Full 3 FS Model & DCF'!K29+'Full 3 FS Model & DCF'!K30+'Full 3 FS Model & DCF'!K31+'Full 3 FS Model & DCF'!K33)/('Full 3 FS Model & DCF'!K44+'Full 3 FS Model & DCF'!K45) -> 0.89008932 | K17: =('Full 3 FS Model & DCF'!L29+'Full 3 FS Model & DCF'!L30+'Full 3 FS Model & DCF'!L31+'Full 3 FS Model & DCF'!L33)/('Full 3 FS Model & DCF'!L44+'Full 3 FS Model & DCF'!L45) -> 0.56457325 | L17: =('Full 3 FS Model & DCF'!M29+'Full 3 FS Model & DCF'!M30+'Full 3 FS Model & DCF'!M31+'Full 3 FS Model & DCF'!M33)/('Full 3 FS Model & DCF'!M44+'Full 3 FS Model & DCF'!M45) -> 0.50691251 | M17: =('Full 3 FS Model & DCF'!N29+'Full 3 FS Model & DCF'!N30+'Full 3 FS Model & DCF'!N31+'Full 3 FS Model & DCF'!N33)/('Full 3 FS Model & DCF'!N44+'Full 3 FS Model & DCF'!N45) -> 0.61852071 | N17: =('Full 3 FS Model & DCF'!O29+'Full 3 FS Model & DCF'!O30+'Full 3 FS Model & DCF'!O31+'Full 3 FS Model & DCF'!O33)/('Full 3 FS Model & DCF'!O44+'Full 3 FS Model & DCF'!O45) -> 0.52632835
B19: Turnover Ratios (In days)
B20: Recievables Turnover Ratio | I20: ='Full 3 FS Model & DCF'!J10/'Full 3 FS Model & DCF'!J31 -> 10.693816 | J20: ='Full 3 FS Model & DCF'!K10/'Full 3 FS Model & DCF'!K31 -> 17.026336 | K20: ='Full 3 FS Model & DCF'!L10/'Full 3 FS Model & DCF'!L31 -> 16.851629 | L20: ='Full 3 FS Model & DCF'!M10/'Full 3 FS Model & DCF'!M31 -> 13.584554 | M20: ='Full 3 FS Model & DCF'!N10/'Full 3 FS Model & DCF'!N31 -> 13.801863 | N20: ='Full 3 FS Model & DCF'!O10/'Full 3 FS Model & DCF'!O31 -> 14.139662
B21: Inventory Turnover Ratios | I21: ='Full 3 FS Model & DCF'!J10/'Full 3 FS Model & DCF'!J32 -> 6.3089151 | J21: ='Full 3 FS Model & DCF'!K10/'Full 3 FS Model & DCF'!K32 -> 5.5133254 | K21: ='Full 3 FS Model & DCF'!L10/'Full 3 FS Model & DCF'!L32 -> 5.6967934 | L21: ='Full 3 FS Model & DCF'!M10/'Full 3 FS Model & DCF'!M32 -> 5.6960231 | M21: ='Full 3 FS Model & DCF'!N10/'Full 3 FS Model & DCF'!N32 -> 6.3709302 | N21: ='Full 3 FS Model & DCF'!O10/'Full 3 FS Model & DCF'!O32 -> 5.4619518
B22: Payables Turnover Ratio | I22: ='Full 3 FS Model & DCF'!J10/'Full 3 FS Model & DCF'!J44 -> 5.8722734 | J22: ='Full 3 FS Model & DCF'!K10/'Full 3 FS Model & DCF'!K44 -> 4.9923509 | K22: ='Full 3 FS Model & DCF'!L10/'Full 3 FS Model & DCF'!L44 -> 5.3959117 | L22: ='Full 3 FS Model & DCF'!M10/'Full 3 FS Model & DCF'!M44 -> 5.2729522 | M22: ='Full 3 FS Model & DCF'!N10/'Full 3 FS Model & DCF'!N44 -> 5.1220047 | N22: ='Full 3 FS Model & DCF'!O10/'Full 3 FS Model & DCF'!O44 -> 4.4465763
B24: Du Pont Analysis
B25: ROE | I25: =I12 -> 0.21919237 | J25: =J12 -> 0.22130272 | K25: =K12 -> 0.20809421 | L25: =L12 -> 0.18978164 | M25: =M12 -> 0.18363723 | N25: =N12 -> 0.16108878
B26: NPM | I26: =I8 -> 0.16636009 | J26: =J8 -> 0.17737106 | K26: =K8 -> 0.16017552 | L26: =L8 -> 0.14769959 | M26: =M8 -> 0.14606728 | N26: =N8 -> 0.13849061
B27: Assets Turnover | I27: ='Full 3 FS Model & DCF'!J10/'Full 3 FS Model & DCF'!J40 -> 0.93046619 | J27: ='Full 3 FS Model & DCF'!K10/'Full 3 FS Model & DCF'!K40 -> 0.88149123 | K27: ='Full 3 FS Model & DCF'!L10/'Full 3 FS Model & DCF'!L40 -> 0.88637335 | L27: ='Full 3 FS Model & DCF'!M10/'Full 3 FS Model & DCF'!M40 -> 0.84441025 | M27: ='Full 3 FS Model & DCF'!N10/'Full 3 FS Model & DCF'!N40 -> 0.82022565 | N27: ='Full 3 FS Model & DCF'!O10/'Full 3 FS Model & DCF'!O40 -> 0.7774199
B28: Asset/Equity | I28: ='Full 3 FS Model & DCF'!J40/'Full 3 FS Model & DCF'!J54 -> 1.4160406 | J28: ='Full 3 FS Model & DCF'!K40/'Full 3 FS Model & DCF'!K54 -> 1.4154221 | K28: ='Full 3 FS Model & DCF'!L40/'Full 3 FS Model & DCF'!L54 -> 1.465707 | L28: ='Full 3 FS Model & DCF'!M40/'Full 3 FS Model & DCF'!M54 -> 1.5216733 | M28: ='Full 3 FS Model & DCF'!N40/'Full 3 FS Model & DCF'!N54 -> 1.532761 | N28: ='Full 3 FS Model & DCF'!O40/'Full 3 FS Model & DCF'!O54 -> 1.4961989
B30: Cash Conversion Cycle
B31: Recievables Days | I31: =365/I20 -> 34.131875 | J31: =365/J20 -> 21.437377 | K31: =365/K20 -> 21.659627 | L31: =365/L20 -> 26.868752 | M31: =365/M20 -> 26.445706 | N31: =365/N20 -> 25.813912
B32: Inventory Days | I32: =365/I21 -> 57.854638 | J32: =365/J21 -> 66.203239 | K32: =365/K21 -> 64.071132 | L32: =365/L21 -> 64.079796 | M32: =365/M21 -> 57.291477 | N32: =365/N21 -> 66.825928
B33: Payables Days | I33: =365/I22 -> 62.156507 | J33: =365/J22 -> 73.111848 | K33: =365/K22 -> 67.643805 | L33: =365/L22 -> 69.221185 | M33: =365/M22 -> 71.261161 | N33: =365/N22 -> 82.085625
B35: Cash Conversion Cycle | I35: =I31+I32-I33 -> 29.830007 | J35: =J31+J32-J33 -> 14.528769 | K35: =K31+K32-K33 -> 18.086954 | L35: =L31+L32-L33 -> 21.727363 | M35: =M31+M32-M33 -> 12.476022 | N35: =N31+N32-N33 -> 10.554215
B39: Back to cover

Sheet Comp- Valuation- Dabur
B1: Dabur India Ltd.
B4: Comparable Company Valuation
B6: (Amounts in crores)
D7: Market Data | K7: Financial Data | O7: Valuation
D8: Price | E8: No. of shares | F8: Market Cap | G8: Debt | H8: Cash and Equivalents | I8: EV | K8: Sales | L8: EBITDA | M8: Earnings | O8: EV/Sales | P8: EV/EBITDA | Q8: P/E
B9: Company Name | D9: (₹ Share) | E9: (in crore) | F9: (in crore) | G9: (in crore) | H9: (in crore) | I9: (in crore) | K9: (in crore) | L9: (in crore) | M9: (in crore) | O9: x | P9: x | Q9: x
B10: ='Comp value data'!B5 -> Dabur India | D10: ='Comp value data'!C5 -> 518.65 | E10: ='Comp value data'!D5 -> 177.37 | F10: =D10*E10 -> 91992.95 | G10: ='Comp value data'!F5 -> 950.37 | H10: ='Comp value data'!G5 -> 578.01 | I10: =F10+G10-H10 -> 92365.31 | K10: ='Comp value data'!H5 -> 12781.29 | L10: ='Comp value data'!I5 -> 2917.94 | M10: ='Comp value data'!J5 -> 1808.97 | O10: =I10/K10 -> 7.2266031 | P10: =I10/L10 -> 31.654287 | Q10: =F10/M10 -> 50.853773
B11: ='Comp value data'!B6 -> Godrej Consumer | D11: ='Comp value data'!C6 -> 1121.8 | E11: ='Comp value data'!D6 -> 102.31 | F11: =D11*E11 -> 114771.36 | G11: ='Comp value data'!F6 -> 4113.49 | H11: ='Comp value data'!G6 -> 1080.34 | I11: =F11+G11-H11 -> 117804.51 | K11: ='Comp value data'!H6 -> 14853.33 | L11: ='Comp value data'!I6 -> 3247.18 | M11: ='Comp value data'!J6 -> 1882.61 | O11: =I11/K11 -> 7.931185 | P11: =I11/L11 -> 36.27902 | Q11: =F11/M11 -> 60.963959
B12: ='Comp value data'!B7 -> Colgate-Palmoliv | D12: ='Comp value data'!C7 -> 2167.2 | E12: ='Comp value data'!D7 -> 27.2 | F12: =D12*E12 -> 58947.84 | G12: ='Comp value data'!F7 -> 59.99 | H12: ='Comp value data'!G7 -> 1347.47 | I12: =F12+G12-H12 -> 57660.36 | K12: ='Comp value data'!H7 -> 5877.91 | L12: ='Comp value data'!I7 -> 1942.8 | M12: ='Comp value data'!J7 -> 1325.91 | O12: =I12/K12 -> 9.8096704 | P12: =I12/L12 -> 29.678999 | Q12: =F12/M12 -> 44.458402
B13: ='Comp value data'!B8 -> P & G Hygiene | D13: ='Comp value data'!C8 -> 13174 | E13: ='Comp value data'!D8 -> 3.25 | F13: =D13*E13 -> 42815.5 | G13: ='Comp value data'!F8 -> 2.06 | H13: ='Comp value data'!G8 -> 793.12 | I13: =F13+G13-H13 -> 42024.44 | K13: ='Comp value data'!H8 -> 4326.46 | L13: ='Comp value data'!I8 -> 1177.94 | M13: ='Comp value data'!J8 -> 826.61 | O13: =I13/K13 -> 9.7133546 | P13: =I13/L13 -> 35.676214 | Q13: =F13/M13 -> 51.796494
B14: ='Comp value data'!B9 -> Gillette India | D14: ='Comp value data'!C9 -> 8480.5 | E14: ='Comp value data'!D9 -> 3.26 | F14: =D14*E14 -> 27646.43 | G14: ='Comp value data'!F9 -> 0.05 | H14: ='Comp value data'!G9 -> 591.52 | I14: =F14+G14-H14 -> 27054.96 | K14: ='Comp value data'!H9 -> 2970.55 | L14: ='Comp value data'!I9 -> 862.8 | M14: ='Comp value data'!J9 -> 573.99 | O14: =I14/K14 -> 9.1077275 | P14: =I14/L14 -> 31.357163 | Q14: =F14/M14 -> 48.165351
B15: ='Comp value data'!B10 -> Emami | D15: ='Comp value data'!C10 -> 514.1 | E15: ='Comp value data'!D10 -> 43.65 | F15: =D15*E15 -> 22440.465 | G15: ='Comp value data'!F10 -> 89.79 | H15: ='Comp value data'!G10 -> 272.9 | I15: =F15+G15-H15 -> 22257.355 | K15: ='Comp value data'!H10 -> 3807.21 | L15: ='Comp value data'!I10 -> 1090.24 | M15: ='Comp value data'!J10 -> 818.08 | O15: =I15/K15 -> 5.8461065 | P15: =I15/L15 -> 20.415097 | Q15: =F15/M15 -> 27.430649
B16: ='Comp value data'!B11 -> Honasa Consumer | D16: ='Comp value data'!C11 -> 273.95 | E16: ='Comp value data'!D11 -> 32.54 | F16: =D16*E16 -> 8914.333 | G16: ='Comp value data'!F11 -> 109.79 | H16: ='Comp value data'!G11 -> 294.99 | I16: =F16+G16-H16 -> 8729.133 | K16: ='Comp value data'!H11 -> 1994.23 | L16: ='Comp value data'!I11 -> 141.55 | M16: ='Comp value data'!J11 -> 71.17 | O16: =I16/K16 -> 4.3771947 | P16: =I16/L16 -> 61.668195 | Q16: =F16/M16 -> 125.25408
B18: Average | O18: =AVERAGE(O10:O16) -> 7.7159774 | P18: =AVERAGE(P10:P16) -> 35.246996 | Q18: =AVERAGE(Q10:Q16) -> 58.41753
B19: Median | O19: =MEDIAN(O10:O16) -> 7.931185 | P19: =MEDIAN(P10:P16) -> 31.654287 | Q19: =MEDIAN(Q10:Q16) -> 50.853773
B22: Metric | E22: Comps | F22: EV | H22: Net Debt | I22: Equity Value | K22: Shares | L22: Share Price
B23: EV/Revenue | E23: =O18 -> 7.7159774 | F23: =E23*K10 -> 98620.145 | H23: =G10-H10 -> 372.36 | I23: =F23-H23 -> 98247.785 | K23: =E10 -> 177.37 | L23: =I23/K23 -> 553.91433
B24: EV/EBITDA | E24: =P18 -> 35.246996 | F24: =E24*L10 -> 102848.62 | H24: =G10-H10 -> 372.36 | I24: =F24-H24 -> 102476.26 | K24: =E10 -> 177.37 | L24: =I24/K24 -> 577.75419
B25: P/E | E25: =Q18 -> 58.41753 | F25: =I25+H25 -> 106047.92 | H25: =G10-H10 -> 372.36 | I25: =E25*M10 -> 105675.56 | K25: =E10 -> 177.37 | L25: =I25/K25 -> 595.79162
B28: Back to cover

Sheet Scenarios
B1: Dabur India Ltd.
B4: Scenarios
B6: Revenue Growth
B7: Scenarios | D7: Growth(%) | G7: 2026 | H7: =G7+1 -> 2027 | I7: =H7+1 -> 2028 | J7: =I7+1 -> 2029 | K7: =J7+1 -> 2030 | L7: Long Term Growth
B8: Base Case | D8: =AVERAGE('Full 3 FS Model & DCF'!K115:O115) -> 0.076979931 | G8: =D8 -> 0.076979931 | H8: =G8*(1-$D$11) -> 0.073130934 | I8: =H8*(1-$D$11) -> 0.069474387 | J8: =I8*(1-$D$11) -> 0.066000668 | K8: =J8*(1-$D$11) -> 0.062700635 | L8: 0.06
B9: Best Case | D9: =MAX('Full 3 FS Model & DCF'!K115:O115) -> 0.13878672 | G9: =D9 -> 0.13878672 | H9: =G9*(1-$D$11) -> 0.13184738 | I9: =H9*(1-$D$11) -> 0.12525501 | J9: =I9*(1-$D$11) -> 0.11899226 | K9: =J9*(1-$D$11) -> 0.11304265
B10: Worst Case | D10: =MIN('Full 3 FS Model & DCF'!K115:O115) -> 0.012824885 | G10: =D10 -> 0.012824885 | H10: =G10*(1-$D$11) -> 0.012183641 | I10: =H10*(1-$D$11) -> 0.011574459 | J10: =I10*(1-$D$11) -> 0.010995736 | K10: =J10*(1-$D$11) -> 0.010445949
B11: Annual Growth Tapering | D11: 0.05
B14: COGS (% of Revenue)
B15: Scenarios | D15: Growth(%) | G15: 2026 | H15: =G15+1 -> 2027 | I15: =H15+1 -> 2028 | J15: =I15+1 -> 2029 | K15: =J15+1 -> 2030
B16: Base Case | D16: =AVERAGE('Full 3 FS Model & DCF'!J118:O118) -> 0.51722697 | G16: =D16 -> 0.51722697 | H16: =G16 -> 0.51722697 | I16: =H16 -> 0.51722697 | J16: =I16 -> 0.51722697 | K16: =J16 -> 0.51722697
B17: Best Case | D17: =MIN('Full 3 FS Model & DCF'!J118:O118) -> 0.50085079 | G17: =D17 -> 0.50085079 | H17: =G17 -> 0.50085079 | I17: =H17 -> 0.50085079 | J17: =I17 -> 0.50085079 | K17: =J17 -> 0.50085079
B18: Worst Case | D18: =MAX('Full 3 FS Model & DCF'!J118:O118) -> 0.54368862 | G18: =D18 -> 0.54368862 | H18: =G18 -> 0.54368862 | I18: =H18 -> 0.54368862 | J18: =I18 -> 0.54368862 | K18: =J18 -> 0.54368862
B20: Salary & Benefit Expenses (% of Revenue)
B21: Scenarios | D21: Growth(%) | G21: 2026 | H21: =G21+1 -> 2027 | I21: =H21+1 -> 2028 | J21: =I21+1 -> 2029 | K21: =J21+1 -> 2030
B22: Base Case | D22: =AVERAGE('Full 3 FS Model & DCF'!J120:O120) -> 0.10291344 | G22: =D22 -> 0.10291344 | H22: =G22 -> 0.10291344 | I22: =H22 -> 0.10291344 | J22: =I22 -> 0.10291344 | K22: =J22 -> 0.10291344
B23: Best Case | D23: =MIN('Full 3 FS Model & DCF'!J120:O120) -> 0.098613257 | G23: =D23 -> 0.098613257 | H23: =G23 -> 0.098613257 | I23: =H23 -> 0.098613257 | J23: =I23 -> 0.098613257 | K23: =J23 -> 0.098613257
B24: Worst Case | D24: =MAX('Full 3 FS Model & DCF'!J120:O120) -> 0.1088907 | G24: =D24 -> 0.1088907 | H24: =G24 -> 0.1088907 | I24: =H24 -> 0.1088907 | J24: =I24 -> 0.1088907 | K24: =J24 -> 0.1088907
B26: Other Expenses (% of Revenue)
B27: Scenarios | D27: Growth(%) | G27: 2026 | H27: =G27+1 -> 2027 | I27: =H27+1 -> 2028 | J27: =I27+1 -> 2029 | K27: =J27+1 -> 2030
B28: Base Case | D28: =AVERAGE('Full 3 FS Model & DCF'!J123:O123) -> 0.18186868 | G28: =D28 -> 0.18186868 | H28: =G28 -> 0.18186868 | I28: =H28 -> 0.18186868 | J28: =I28 -> 0.18186868 | K28: =J28 -> 0.18186868
B29: Best Case | D29: =MIN('Full 3 FS Model & DCF'!J123:O123) -> 0.17000162 | G29: =D29 -> 0.17000162 | H29: =G29 -> 0.17000162 | I29: =H29 -> 0.17000162 | J29: =I29 -> 0.17000162 | K29: =J29 -> 0.17000162
B30: Worst Case | D30: =MAX('Full 3 FS Model & DCF'!J123:O123) -> 0.1926803 | G30: =D30 -> 0.1926803 | H30: =G30 -> 0.1926803 | I30: =H30 -> 0.1926803 | J30: =I30 -> 0.1926803 | K30: =J30 -> 0.1926803
B32: D&A Expenses(% of PPE)
B33: Scenarios | D33: Growth(%) | G33: 2026 | H33: =G33+1 -> 2027 | I33: =H33+1 -> 2028 | J33: =I33+1 -> 2029 | K33: =J33+1 -> 2030
B34: Base Case | D34: =AVERAGE('Full 3 FS Model & DCF'!K126:O126) -> 0.12417227 | G34: =D34 -> 0.12417227 | H34: =G34 -> 0.12417227 | I34: =H34 -> 0.12417227 | J34: =I34 -> 0.12417227 | K34: =J34 -> 0.12417227
B35: Best Case | D35: =MIN('Full 3 FS Model & DCF'!K126:O126) -> 0.11638265 | G35: =D35 -> 0.11638265 | H35: =G35 -> 0.11638265 | I35: =H35 -> 0.11638265 | J35: =I35 -> 0.11638265 | K35: =J35 -> 0.11638265
B36: Worst Case | D36: =MAX('Full 3 FS Model & DCF'!K126:O126) -> 0.13980443 | G36: =D36 -> 0.13980443 | H36: =G36 -> 0.13980443 | I36: =H36 -> 0.13980443 | J36: =I36 -> 0.13980443 | K36: =J36 -> 0.13980443
B38: Interest (% of Debt)
B39: Scenarios | D39: Growth(%) | G39: 2026 | H39: =G39+1 -> 2027 | I39: =H39+1 -> 2028 | J39: =I39+1 -> 2029 | K39: =J39+1 -> 2030
B40: Base Case | D40: =AVERAGE('Full 3 FS Model & DCF'!K129:O129) -> 0.088660428 | G40: =D40 -> 0.088660428 | H40: =G40 -> 0.088660428 | I40: =H40 -> 0.088660428 | J40: =I40 -> 0.088660428 | K40: =J40 -> 0.088660428
B41: Best Case | D41: =MIN('Full 3 FS Model & DCF'!K129:O129) -> 0.065955944 | G41: =D41 -> 0.065955944 | H41: =G41 -> 0.065955944 | I41: =H41 -> 0.065955944 | J41: =I41 -> 0.065955944 | K41: =J41 -> 0.065955944
B42: Worst Case | D42: =MAX('Full 3 FS Model & DCF'!K129:O129) -> 0.11977232 | G42: =D42 -> 0.11977232 | H42: =G42 -> 0.11977232 | I42: =H42 -> 0.11977232 | J42: =I42 -> 0.11977232 | K42: =J42 -> 0.11977232
B44: Other Income (Expenses)(% of Revenue)
B45: Scenarios | D45: Growth(%) | G45: 2026 | H45: =G45+1 -> 2027 | I45: =H45+1 -> 2028 | J45: =I45+1 -> 2029 | K45: =J45+1 -> 2030
B46: Base Case | D46: =AVERAGE('Full 3 FS Model & DCF'!J132:O132) -> 0.034535944 | G46: =D46 -> 0.034535944 | H46: =G46 -> 0.034535944 | I46: =H46 -> 0.034535944 | J46: =I46 -> 0.034535944 | K46: =J46 -> 0.034535944
B47: Best Case | D47: =MAX('Full 3 FS Model & DCF'!J132:O132) -> 0.043786998 | G47: =D47 -> 0.043786998 | H47: =G47 -> 0.043786998 | I47: =H47 -> 0.043786998 | J47: =I47 -> 0.043786998 | K47: =J47 -> 0.043786998
B48: Worst Case | D48: =MIN('Full 3 FS Model & DCF'!J132:O132) -> 0.023586819 | G48: =D48 -> 0.023586819 | H48: =G48 -> 0.023586819 | I48: =H48 -> 0.023586819 | J48: =I48 -> 0.023586819 | K48: =J48 -> 0.023586819
B50: Tax Rate (% of EBT)
B51: Scenarios | D51: Growth(%) | G51: 2026 | H51: =G51+1 -> 2027 | I51: =H51+1 -> 2028 | J51: =I51+1 -> 2029 | K51: =J51+1 -> 2030
...

Sheet Common-Size Statement
A1: Dabur India Ltd.
A4: Common Size Statement
A6: Common Size Income Statement
A7: Particulars | E7: ='Other Key Financial Ratio'!I4 -> 2020 | F7: ='Other Key Financial Ratio'!J4 -> 2021 | G7: ='Other Key Financial Ratio'!K4 -> 2022 | H7: ='Other Key Financial Ratio'!L4 -> 2023 | I7: ='Other Key Financial Ratio'!M4 -> 2024 | J7: ='Other Key Financial Ratio'!N4 -> 2025 | K7: Trends
C9: Income
D10: Revenue | E10: ='Full 3 FS Model & DCF'!J10/'Full 3 FS Model & DCF'!J10 -> 1 | F10: ='Full 3 FS Model & DCF'!K10/'Full 3 FS Model & DCF'!K10 -> 1 | G10: ='Full 3 FS Model & DCF'!L10/'Full 3 FS Model & DCF'!L10 -> 1 | H10: ='Full 3 FS Model & DCF'!M10/'Full 3 FS Model & DCF'!M10 -> 1 | I10: ='Full 3 FS Model & DCF'!N10/'Full 3 FS Model & DCF'!N10 -> 1 | J10: ='Full 3 FS Model & DCF'!O10/'Full 3 FS Model & DCF'!O10 -> 1
D11: Cost of Good Sold | E11: =-'Full 3 FS Model & DCF'!J11/'Full 3 FS Model & DCF'!J10 -> 0.50097029 | F11: =-'Full 3 FS Model & DCF'!K11/'Full 3 FS Model & DCF'!K10 -> 0.50085079 | G11: =-'Full 3 FS Model & DCF'!L11/'Full 3 FS Model & DCF'!L10 -> 0.51794065 | H11: =-'Full 3 FS Model & DCF'!M11/'Full 3 FS Model & DCF'!M10 -> 0.54368862 | I11: =-'Full 3 FS Model & DCF'!N11/'Full 3 FS Model & DCF'!N10 -> 0.51974805 | J11: =-'Full 3 FS Model & DCF'!O11/'Full 3 FS Model & DCF'!O10 -> 0.52016343
D13: Gross Profit | E13: ='Full 3 FS Model & DCF'!J12/'Full 3 FS Model & DCF'!J10 -> 0.49902971 | F13: ='Full 3 FS Model & DCF'!K12/'Full 3 FS Model & DCF'!K10 -> 0.49914921 | G13: ='Full 3 FS Model & DCF'!L12/'Full 3 FS Model & DCF'!L10 -> 0.48205935 | H13: ='Full 3 FS Model & DCF'!M12/'Full 3 FS Model & DCF'!M10 -> 0.45631138 | I13: ='Full 3 FS Model & DCF'!N12/'Full 3 FS Model & DCF'!N10 -> 0.48025195 | J13: ='Full 3 FS Model & DCF'!O12/'Full 3 FS Model & DCF'!O10 -> 0.47983657
C15: Expenses
D16: Salaries and Benefit expenses | E16: =-'Full 3 FS Model & DCF'!J14/'Full 3 FS Model & DCF'!J10 -> 0.1088907 | F16: =-'Full 3 FS Model & DCF'!K14/'Full 3 FS Model & DCF'!K10 -> 0.10808386 | G16: =-'Full 3 FS Model & DCF'!L14/'Full 3 FS Model & DCF'!L10 -> 0.099180984 | H16: =-'Full 3 FS Model & DCF'!M14/'Full 3 FS Model & DCF'!M10 -> 0.098613257 | I16: =-'Full 3 FS Model & DCF'!N14/'Full 3 FS Model & DCF'!N10 -> 0.099932199 | J16: =-'Full 3 FS Model & DCF'!O14/'Full 3 FS Model & DCF'!O10 -> 0.10277965
D17: Other Expenses | E17: =-'Full 3 FS Model & DCF'!J15/'Full 3 FS Model & DCF'!J10 -> 0.18420675 | F17: =-'Full 3 FS Model & DCF'!K15/'Full 3 FS Model & DCF'!K10 -> 0.18161614 | G17: =-'Full 3 FS Model & DCF'!L15/'Full 3 FS Model & DCF'!L10 -> 0.17589184 | H17: =-'Full 3 FS Model & DCF'!M15/'Full 3 FS Model & DCF'!M10 -> 0.17000162 | I17: =-'Full 3 FS Model & DCF'!N15/'Full 3 FS Model & DCF'!N10 -> 0.18681539 | J17: =-'Full 3 FS Model & DCF'!O15/'Full 3 FS Model & DCF'!O10 -> 0.1926803
D19: EBITDA | E19: ='Full 3 FS Model & DCF'!J16/'Full 3 FS Model & DCF'!J10 -> 0.20593226 | F19: ='Full 3 FS Model & DCF'!K16/'Full 3 FS Model & DCF'!K10 -> 0.20944921 | G19: ='Full 3 FS Model & DCF'!L16/'Full 3 FS Model & DCF'!L10 -> 0.20698652 | H19: ='Full 3 FS Model & DCF'!M16/'Full 3 FS Model & DCF'!M10 -> 0.1876965 | I19: ='Full 3 FS Model & DCF'!N16/'Full 3 FS Model & DCF'!N10 -> 0.19350436 | J19: ='Full 3 FS Model & DCF'!O16/'Full 3 FS Model & DCF'!O10 -> 0.18437661
D20: Depreciation and amortisation expense | E20: =-'Full 3 FS Model & DCF'!J17/'Full 3 FS Model & DCF'!J10 -> 0.025328629 | F20: =-'Full 3 FS Model & DCF'!K17/'Full 3 FS Model & DCF'!K10 -> 0.025113866 | G20: =-'Full 3 FS Model & DCF'!L17/'Full 3 FS Model & DCF'!L10 -> 0.023225037 | H20: =-'Full 3 FS Model & DCF'!M17/'Full 3 FS Model & DCF'!M10 -> 0.026969902 | I20: =-'Full 3 FS Model & DCF'!N17/'Full 3 FS Model & DCF'!N10 -> 0.032183947 | J20: =-'Full 3 FS Model & DCF'!O17/'Full 3 FS Model & DCF'!O10 -> 0.035468981
D22: EBIT | E22: ='Full 3 FS Model & DCF'!J18/'Full 3 FS Model & DCF'!J10 -> 0.18060364 | F22: ='Full 3 FS Model & DCF'!K18/'Full 3 FS Model & DCF'!K10 -> 0.18433534 | G22: ='Full 3 FS Model & DCF'!L18/'Full 3 FS Model & DCF'!L10 -> 0.18376148 | H22: ='Full 3 FS Model & DCF'!M18/'Full 3 FS Model & DCF'!M10 -> 0.1607266 | I22: ='Full 3 FS Model & DCF'!N18/'Full 3 FS Model & DCF'!N10 -> 0.16132041 | J22: ='Full 3 FS Model & DCF'!O18/'Full 3 FS Model & DCF'!O10 -> 0.14890763
D23: Interest | E23: =-'Full 3 FS Model & DCF'!J19/'Full 3 FS Model & DCF'!J10 -> 0.0056919041 | F23: =-'Full 3 FS Model & DCF'!K19/'Full 3 FS Model & DCF'!K10 -> 0.0032222472 | G23: =-'Full 3 FS Model & DCF'!L19/'Full 3 FS Model & DCF'!L10 -> 0.003544966 | H23: =-'Full 3 FS Model & DCF'!M19/'Full 3 FS Model & DCF'!M10 -> 0.006785841 | I23: =-'Full 3 FS Model & DCF'!N19/'Full 3 FS Model & DCF'!N10 -> 0.010011279 | J23: =-'Full 3 FS Model & DCF'!O19/'Full 3 FS Model & DCF'!O10 -> 0.013014314
D24: Other Income (Expenses) | E24: ='Full 3 FS Model & DCF'!J20/'Full 3 FS Model & DCF'!J10 -> 0.023586819 | F24: ='Full 3 FS Model & DCF'!K20/'Full 3 FS Model & DCF'!K10 -> 0.034020279 | G24: ='Full 3 FS Model & DCF'!L20/'Full 3 FS Model & DCF'!L10 -> 0.028300951 | H24: ='Full 3 FS Model & DCF'!M20/'Full 3 FS Model & DCF'!M10 -> 0.038629163 | I24: ='Full 3 FS Model & DCF'!N20/'Full 3 FS Model & DCF'!N10 -> 0.038891455 | J24: ='Full 3 FS Model & DCF'!O20/'Full 3 FS Model & DCF'!O10 -> 0.043786998
D26: Earning Before Tax | E26: ='Full 3 FS Model & DCF'!J21/'Full 3 FS Model & DCF'!J10 -> 0.19849855 | F26: ='Full 3 FS Model & DCF'!K21/'Full 3 FS Model & DCF'!K10 -> 0.21513337 | G26: ='Full 3 FS Model & DCF'!L21/'Full 3 FS Model & DCF'!L10 -> 0.20851747 | H26: ='Full 3 FS Model & DCF'!M21/'Full 3 FS Model & DCF'!M10 -> 0.19256992 | I26: ='Full 3 FS Model & DCF'!N21/'Full 3 FS Model & DCF'!N10 -> 0.19020059 | J26: ='Full 3 FS Model & DCF'!O21/'Full 3 FS Model & DCF'!O10 -> 0.17968032
D27: Tax | E27: =-'Full 3 FS Model & DCF'!J22/'Full 3 FS Model & DCF'!J10 -> 0.032138462 | F27: =-'Full 3 FS Model & DCF'!K22/'Full 3 FS Model & DCF'!K10 -> 0.037762311 | G27: =-'Full 3 FS Model & DCF'!L22/'Full 3 FS Model & DCF'!L10 -> 0.048341948 | H27: =-'Full 3 FS Model & DCF'!M22/'Full 3 FS Model & DCF'!M10 -> 0.044870333 | I27: =-'Full 3 FS Model & DCF'!N22/'Full 3 FS Model & DCF'!N10 -> 0.044133309 | J27: =-'Full 3 FS Model & DCF'!O22/'Full 3 FS Model & DCF'!O10 -> 0.041189707
D29: Net Profit | E29: ='Full 3 FS Model & DCF'!J23/'Full 3 FS Model & DCF'!J10 -> 0.16636009 | F29: ='Full 3 FS Model & DCF'!K23/'Full 3 FS Model & DCF'!K10 -> 0.17737106 | G29: ='Full 3 FS Model & DCF'!L23/'Full 3 FS Model & DCF'!L10 -> 0.16017552 | H29: ='Full 3 FS Model & DCF'!M23/'Full 3 FS Model & DCF'!M10 -> 0.14769959 | I29: ='Full 3 FS Model & DCF'!N23/'Full 3 FS Model & DCF'!N10 -> 0.14606728 | J29: ='Full 3 FS Model & DCF'!O23/'Full 3 FS Model & DCF'!O10 -> 0.13849061
A32: Common Size Balancesheet
B34: Assets
C35: Current Assets:
D36: Cash | E36: ='Full 3 FS Model & DCF'!J29/'Full 3 FS Model & DCF'!$J$40 -> 0.017526173 | F36: ='Full 3 FS Model & DCF'!K29/'Full 3 FS Model & DCF'!$K$40 -> 0.022239062 | G36: ='Full 3 FS Model & DCF'!L29/'Full 3 FS Model & DCF'!$L$40 -> 0.020831892 | H36: ='Full 3 FS Model & DCF'!M29/'Full 3 FS Model & DCF'!$M$40 -> 0.010752602 | I36: ='Full 3 FS Model & DCF'!N29/'Full 3 FS Model & DCF'!$N$40 -> 0.016372759 | J36: ='Full 3 FS Model & DCF'!O29/'Full 3 FS Model & DCF'!$O$40 -> 0.0069288452
D37: Bank deposits | E37: ='Full 3 FS Model & DCF'!J30/'Full 3 FS Model & DCF'!$J$40 -> 0.069214166 | F37: ='Full 3 FS Model & DCF'!K30/'Full 3 FS Model & DCF'!$K$40 -> 0.10028459 | G37: ='Full 3 FS Model & DCF'!L30/'Full 3 FS Model & DCF'!$L$40 -> 0.025579326 | H37: ='Full 3 FS Model & DCF'!M30/'Full 3 FS Model & DCF'!$M$40 -> 0.01311668 | I37: ='Full 3 FS Model & DCF'!N30/'Full 3 FS Model & DCF'!$N$40 -> 0.027690859 | J37: ='Full 3 FS Model & DCF'!O30/'Full 3 FS Model & DCF'!$O$40 -> 0.024365129
D38: Accounts Receivables | E38: ='Full 3 FS Model & DCF'!J31/'Full 3 FS Model & DCF'!$J$40 -> 0.087009742 | F38: ='Full 3 FS Model & DCF'!K31/'Full 3 FS Model & DCF'!$K$40 -> 0.05177222 | G38: ='Full 3 FS Model & DCF'!L31/'Full 3 FS Model & DCF'!$L$40 -> 0.052598675 | H38: ='Full 3 FS Model & DCF'!M31/'Full 3 FS Model & DCF'!$M$40 -> 0.062159587 | I38: ='Full 3 FS Model & DCF'!N31/'Full 3 FS Model & DCF'!$N$40 -> 0.05942862 | J38: ='Full 3 FS Model & DCF'!O31/'Full 3 FS Model & DCF'!$O$40 -> 0.054981504
D39: Inventory | E39: ='Full 3 FS Model & DCF'!J32/'Full 3 FS Model & DCF'!$J$40 -> 0.14748434 | F39: ='Full 3 FS Model & DCF'!K32/'Full 3 FS Model & DCF'!$K$40 -> 0.15988377 | G39: ='Full 3 FS Model & DCF'!L32/'Full 3 FS Model & DCF'!$L$40 -> 0.15559163 | H39: ='Full 3 FS Model & DCF'!M32/'Full 3 FS Model & DCF'!$M$40 -> 0.14824558 | I39: ='Full 3 FS Model & DCF'!N32/'Full 3 FS Model & DCF'!$N$40 -> 0.12874504 | J39: ='Full 3 FS Model & DCF'!O32/'Full 3 FS Model & DCF'!$O$40 -> 0.14233372
D40: Other Current Assets | E40: ='Full 3 FS Model & DCF'!J33/'Full 3 FS Model & DCF'!$J$40 -> 0.050079057 | F40: ='Full 3 FS Model & DCF'!K33/'Full 3 FS Model & DCF'!$K$40 -> 0.035710829 | G40: ='Full 3 FS Model & DCF'!L33/'Full 3 FS Model & DCF'!$L$40 -> 0.024267107 | H40: ='Full 3 FS Model & DCF'!M33/'Full 3 FS Model & DCF'!$M$40 -> 0.020846806 | I40: ='Full 3 FS Model & DCF'!N33/'Full 3 FS Model & DCF'!$N$40 -> 0.030316055 | J40: ='Full 3 FS Model & DCF'!O33/'Full 3 FS Model & DCF'!$O$40 -> 0.03924943
C42: Non-current Assets:
D43: Property, plant and equipment | E43: ='Full 3 FS Model & DCF'!J36/'Full 3 FS Model & DCF'!$J$40 -> 0.22057706 | F43: ='Full 3 FS Model & DCF'!K36/'Full 3 FS Model & DCF'!$K$40 -> 0.1893782 | G43: ='Full 3 FS Model & DCF'!L36/'Full 3 FS Model & DCF'!$L$40 -> 0.18106106 | H43: ='Full 3 FS Model & DCF'!M36/'Full 3 FS Model & DCF'!$M$40 -> 0.24523504 | I43: ='Full 3 FS Model & DCF'!N36/'Full 3 FS Model & DCF'!$N$40 -> 0.2408376 | J43: ='Full 3 FS Model & DCF'!O36/'Full 3 FS Model & DCF'!$O$40 -> 0.2322769
D44: Goodwill | E44: ='Full 3 FS Model & DCF'!J37/'Full 3 FS Model & DCF'!$J$40 -> 0.035917216 | F44: ='Full 3 FS Model & DCF'!K37/'Full 3 FS Model & DCF'!$K$40 -> 0.030976857 | G44: ='Full 3 FS Model & DCF'!L37/'Full 3 FS Model & DCF'!$L$40 -> 0.020444413 | H44: ='Full 3 FS Model & DCF'!M37/'Full 3 FS Model & DCF'!$M$40 -> 0.029679143 | I44: ='Full 3 FS Model & DCF'!N37/'Full 3 FS Model & DCF'!$N$40 -> 0.026788902 | J44: ='Full 3 FS Model & DCF'!O37/'Full 3 FS Model & DCF'!$O$40 -> 0.025067482
D45: Financial Assets | E45: ='Full 3 FS Model & DCF'!J38/'Full 3 FS Model & DCF'!$J$40 -> 0.36020274 | F45: ='Full 3 FS Model & DCF'!K38/'Full 3 FS Model & DCF'!$K$40 -> 0.3953525 | G45: ='Full 3 FS Model & DCF'!L38/'Full 3 FS Model & DCF'!$L$40 -> 0.5111673 | H45: ='Full 3 FS Model & DCF'!M38/'Full 3 FS Model & DCF'!$M$40 -> 0.46319383 | I45: ='Full 3 FS Model & DCF'!N38/'Full 3 FS Model & DCF'!$N$40 -> 0.4626184 | J45: ='Full 3 FS Model & DCF'!O38/'Full 3 FS Model & DCF'!$O$40 -> 0.46616827
D46: Other Non-current Assets | E46: ='Full 3 FS Model & DCF'!J39/'Full 3 FS Model & DCF'!$J$40 -> 0.01198951 | F46: ='Full 3 FS Model & DCF'!K39/'Full 3 FS Model & DCF'!$K$40 -> 0.014401966 | G46: ='Full 3 FS Model & DCF'!L39/'Full 3 FS Model & DCF'!$L$40 -> 0.0084586061 | H46: ='Full 3 FS Model & DCF'!M39/'Full 3 FS Model & DCF'!$M$40 -> 0.0067707261 | I46: ='Full 3 FS Model & DCF'!N39/'Full 3 FS Model & DCF'!$N$40 -> 0.0072017658 | J46: ='Full 3 FS Model & DCF'!O39/'Full 3 FS Model & DCF'!$O$40 -> 0.0086287236
D47: Total Assets | E47: ='Full 3 FS Model & DCF'!J40/'Full 3 FS Model & DCF'!$J$40 -> 1 | F47: ='Full 3 FS Model & DCF'!K40/'Full 3 FS Model & DCF'!$K$40 -> 1 | G47: ='Full 3 FS Model & DCF'!L40/'Full 3 FS Model & DCF'!$L$40 -> 1 | H47: ='Full 3 FS Model & DCF'!M40/'Full 3 FS Model & DCF'!$M$40 -> 1 | I47: ='Full 3 FS Model & DCF'!N40/'Full 3 FS Model & DCF'!$N$40 -> 1 | J47: ='Full 3 FS Model & DCF'!O40/'Full 3 FS Model & DCF'!$O$40 -> 1
B50: Liability
C51: Current Liabilities
D52: Accounts Payable | E52: ='Full 3 FS Model & DCF'!J44/'Full 3 FS Model & DCF'!$J$40 -> 0.15845076 | F52: ='Full 3 FS Model & DCF'!K44/'Full 3 FS Model & DCF'!$K$40 -> 0.17656836 | G52: ='Full 3 FS Model & DCF'!L44/'Full 3 FS Model & DCF'!$L$40 -> 0.16426758 | H52: ='Full 3 FS Model & DCF'!M44/'Full 3 FS Model & DCF'!$M$40 -> 0.16013994 | I52: ='Full 3 FS Model & DCF'!N44/'Full 3 FS Model & DCF'!$N$40 -> 0.16013762 | J52: ='Full 3 FS Model & DCF'!O44/'Full 3 FS Model & DCF'!$O$40 -> 0.17483561
D53: Other Current Liabilities | E53: ='Full 3 FS Model & DCF'!J45/'Full 3 FS Model & DCF'!$J$40 -> 0.072427761 | F53: ='Full 3 FS Model & DCF'!K45/'Full 3 FS Model & DCF'!$K$40 -> 0.059370543 | G53: ='Full 3 FS Model & DCF'!L45/'Full 3 FS Model & DCF'!$L$40 -> 0.054086725 | H53: ='Full 3 FS Model & DCF'!M45/'Full 3 FS Model & DCF'!$M$40 -> 0.05069659 | I53: ='Full 3 FS Model & DCF'!N45/'Full 3 FS Model & DCF'!$N$40 -> 0.056198372 | J53: ='Full 3 FS Model & DCF'!O45/'Full 3 FS Model & DCF'!$O$40 -> 0.063656019
C54: Non-Current Liabilities
D55: Debt | E55: ='Full 3 FS Model & DCF'!J47/'Full 3 FS Model & DCF'!$J$40 -> 0.04993901 | F55: ='Full 3 FS Model & DCF'!K47/'Full 3 FS Model & DCF'!$K$40 -> 0.046930386 | G55: ='Full 3 FS Model & DCF'!L47/'Full 3 FS Model & DCF'!$L$40 -> 0.083853432 | H55: ='Full 3 FS Model & DCF'!M47/'Full 3 FS Model & DCF'!$M$40 -> 0.08596442 | I55: ='Full 3 FS Model & DCF'!N47/'Full 3 FS Model & DCF'!$N$40 -> 0.09026773 | J55: ='Full 3 FS Model & DCF'!O47/'Full 3 FS Model & DCF'!$O$40 -> 0.054336082
D56: Other Non-Current Liabilities | E56: ='Full 3 FS Model & DCF'!J48/'Full 3 FS Model & DCF'!$J$40 -> 0.0090902191 | F56: ='Full 3 FS Model & DCF'!K48/'Full 3 FS Model & DCF'!$K$40 -> 0.0072452345 | G56: ='Full 3 FS Model & DCF'!L48/'Full 3 FS Model & DCF'!$L$40 -> 0.01222676 | H56: ='Full 3 FS Model & DCF'!M48/'Full 3 FS Model & DCF'!$M$40 -> 0.011740564 | I56: ='Full 3 FS Model & DCF'!N48/'Full 3 FS Model & DCF'!$N$40 -> 0.012096401 | J56: ='Full 3 FS Model & DCF'!O48/'Full 3 FS Model & DCF'!$O$40 -> 0.01346722
...

Sheet WACC Calculation
B1: Dabur India Ltd.
B4: Weighted Average Cost of Capital - WACC
B6: Comparable Companies Beta
B7: (Amounts in crores)
G8: Equity | H8: Total | I8: Debt/ | J8: Debt/ | K8: Tax | L8: Levered | M8: Unlevered
B9: Name | G9: Value | H9: Debt | I9: Equity | J9: Capital | K9: Rate (%) | L9: Beta | M9: Beta
B10: ='Comp value data'!B6 -> Godrej Consumer | G10: ='Comp- Valuation- Dabur'!F11 -> 114771.36 | H10: ='Comp- Valuation- Dabur'!G11 -> 4113.49 | I10: =H10/G10 -> 0.035840737 | J10: =H10/(G10+H10) -> 0.034600625 | K10: ='Comp value data'!P6 -> 0.27883089 | L10: 0.23 | M10: =L10/(1+I10*(1-K10)) -> 0.22420492
B11: ='Comp value data'!B7 -> Colgate-Palmoliv | G11: ='Comp- Valuation- Dabur'!F12 -> 58947.84 | H11: ='Comp- Valuation- Dabur'!G12 -> 59.99 | I11: =H11/G11 -> 0.0010176794 | J11: =H11/(G11+H11) -> 0.0010166447 | K11: ='Comp value data'!P7 -> 0.25693102 | L11: 0.31 | M11: =L11/(1+I11*(1-K11)) -> 0.30976575
B12: ='Comp value data'!B8 -> P & G Hygiene | G12: ='Comp- Valuation- Dabur'!F13 -> 42815.5 | H12: ='Comp- Valuation- Dabur'!G13 -> 2.06 | I12: =H12/G12 -> 4.8113417e-05 | J12: =H12/(G12+H12) -> 4.8111102e-05 | K12: ='Comp value data'!P8 -> 0.26410391 | L12: 0.46 | M12: =L12/(1+I12*(1-K12)) -> 0.45998371 | O12: For levered beta, data extracted from investing.com
B13: ='Comp value data'!B9 -> Gillette India | G13: ='Comp- Valuation- Dabur'!F14 -> 27646.43 | H13: ='Comp- Valuation- Dabur'!G14 -> 0.05 | I13: =H13/G13 -> 1.8085518e-06 | J13: =H13/(G13+H13) -> 1.8085485e-06 | K13: ='Comp value data'!P9 -> 0.24973531 | L13: 0.03 | M13: =L13/(1+I13*(1-K13)) -> 0.029999959
B14: ='Comp value data'!B10 -> Emami | G14: ='Comp- Valuation- Dabur'!F15 -> 22440.465 | H14: ='Comp- Valuation- Dabur'!G15 -> 89.79 | I14: =H14/G14 -> 0.004001254 | J14: =H14/(G14+H14) -> 0.0039853078 | K14: ='Comp value data'!P10 -> 0.095151011 | L14: 0.05 | M14: =L14/(1+I14*(1-K14)) -> 0.049819627
B15: Honasa Consumer | G15: ='Comp- Valuation- Dabur'!F16 -> 8914.333 | H15: ='Comp- Valuation- Dabur'!G16 -> 109.79 | I15: =H15/G15 -> 0.012316121 | J15: =H15/(G15+H15) -> 0.012166279 | K15: ='Comp value data'!P11 -> 0.24517497 | L15: 0.8 | M15: =L15/(1+I15*(1-K15)) -> 0.79263129
B16: Average | I16: =AVERAGE(I10:I15) -> 0.0088709521 | J16: =AVERAGE(J10:J15) -> 0.0086364627 | K16: =AVERAGE(K10:K15) -> 0.23165452 | L16: =AVERAGE(L10:L15) -> 0.31333333 | M16: =AVERAGE(M10:M15) -> 0.31106754
B17: Median | I17: =MEDIAN(I10:I15) -> 0.0025094667 | J17: =MEDIAN(J10:J15) -> 0.0025009762 | K17: =MEDIAN(K10:K15) -> 0.25333316 | L17: =MEDIAN(L10:L15) -> 0.27 | M17: =MEDIAN(M10:M15) -> 0.26698534
B19: Dabur India | G19: ='Comp- Valuation- Dabur'!F10 -> 91992.95 | H19: ='Comp- Valuation- Dabur'!G10 -> 950.37
B22: WACC Calculation
B24: Target Capital Structure
B25: Proportion of Debt | H25: =J16 -> 0.0086364627
B26: Proportion of Equity | H26: =1-H25 -> 0.99136354
B28: Current Capital Structure
B29: Market Cap | H29: =G19 -> 91992.95
B30: Total Debt | H30: =H19 -> 950.37
B31: Debt/Equity | H31: =H30/H29 -> 0.0103309
B33: Cost of Debt
B34: Pre-Tax Cost of debt | H34: =M35/M34 -> 0.032556621 | K34: Total Debt | M34: =703.58+4318.44 -> 5022.02 | O34: (Source: Annual Report)
B35: Tax Rate | H35: ='Comp value data'!P5 -> 0.22710216 | K35: Interest | M35: =-'Full 3 FS Model & DCF'!O108 -> 163.5
B36: After Tax Cost of Debt | H36: =H34*(1-H35) -> 0.025162942
B38: Cost of Equity
B39: Risk-Free Rate | H39: 0.06521
B40: Equity Market Return | H40: ='Market Data'!F13 -> 0.124
B41: Equity Risk Premium | H41: =H40-H39 -> 0.05879
B42: Levered Beta | H42: =M16*(1+H31*(1-H35)) -> 0.31355133
B43: Cost of equity | H43: =H39+(H41*H42) -> 0.083643683
B45: WACC | H45: =H36*H25+H43*H26 -> 0.083138616
B48: Back to cover

Sheet Football Field Analysis
B1: Dabur India Ltd.
B4: Valuation Summary - Football Field
B6: Football Field Data
J7: Market
G8: Comps | H8: DCF | I8: 52-week High/low | J8: Consesus
B9: High | G9: =MAX('Comp- Valuation- Dabur'!L23:L25) -> 595.79162 | H9: 736.11697 | I9: 529.4 | J9: 625
B10: High | G10: =MAX('Comp- Valuation- Dabur'!L24:L26) -> 595.79162 | H10: 736.11697 | I10: 529.4 | J10: 625
B11: Low | G11: =MIN('Comp- Valuation- Dabur'!L23:L25) -> 553.91433 | H11: 437.95659 | I11: 484.15 | J11: 400
B12: Low | G12: =MIN('Comp- Valuation- Dabur'!L23:L25) -> 553.91433 | H12: 437.95659 | I12: 484.15 | J12: 400
B14: Valuation Summary
B32: Back to cover

Sheet Recommendation
B1: Dabur India Ltd.
B4: Recommendation
